<?xml version="1.0" ?>
<!-- =================================================================================== -->
<!-- |    This document was autogenerated by xacro from /home/froscia/ros_ws/install/share/go1_description/robots/go1.urdf.xacro | -->
<!-- |    EDITING THIS FILE BY HAND IS NOT RECOMMENDED                                 | -->
<!-- =================================================================================== -->
<robot name="go1">
  <material name="black">
    <color rgba="0.0 0.0 0.0 1.0"/>
  </material>
  <material name="blue">
    <color rgba="0.0 0.0 0.8 1.0"/>
  </material>
  <material name="green">
    <color rgba="0.0 0.8 0.0 1.0"/>
  </material>
  <material name="grey">
    <color rgba="0.2 0.2 0.2 1.0"/>
  </material>
  <material name="silver">
    <color rgba="0.9137254901960784 0.9137254901960784 0.8470588235294118 1.0"/>
  </material>
  <material name="orange">
    <color rgba="1.0 0.4235294117647059 0.0392156862745098 1.0"/>
  </material>
  <material name="brown">
    <color rgba="0.8705882352941177 0.8117647058823529 0.7647058823529411 1.0"/>
  </material>
  <material name="red">
    <color rgba="0.8 0.0 0.0 1.0"/>
  </material>
  <material name="white">
    <color rgba="1.0 1.0 1.0 1.0"/>
  </material>
  <gazebo>
    <plugin filename="libgazebo_ros_control.so" name="gazebo_ros_controller_manager">
      <!-- if task_period is smaller than sim max_step_size (in world file) it is clamped to that value!!!!!!-->
      <robotNamespace>/go1</robotNamespace>
      <robotSimType>gazebo_ros_control/DefaultRobotHWSim</robotSimType>
      <legacyModeNS>true</legacyModeNS>
      <controlPeriod>0.004</controlPeriod>
    </plugin>
    <plugin filename="libgazebo_ros_p3d.so" name="gazebo_ros_p3d">
      <robotNamespace>/go1</robotNamespace>
      <bodyName>trunk</bodyName>
      <topicName>ground_truth</topicName>
      <frameName>world</frameName>
      <xyzOffsets>0 0 0</xyzOffsets>
      <rpyOffsets>0 0 0</rpyOffsets>
      <gaussianNoise>0</gaussianNoise>
      <alwaysOn>true</alwaysOn>
      <updateRate>250.0</updateRate>
    </plugin>
  </gazebo>
  <!-- Show the trajectory of trunk center. 
    <gazebo>
        <plugin name="3dplot" filename="libLinkPlot3DPlugin.so">
            <frequency>10</frequency>
            <plot>
                <link>base_link</link>
                <pose>0 0 0 0 0 0</pose>
                <material>Gazebo/Yellow</material>
            </plot>
        </plugin>
    </gazebo>-->
  <!-- Apply force to trunck 
    <gazebo>
        <plugin filename="libgazebo_ros_force.so" name="gazebo_ros_force">
            <bodyName>trunk</bodyName>
            <topicName>/apply_force/trunk</topicName>
        </plugin>
    </gazebo>-->
  <!-- IMU -->
  <gazebo reference="imu_link">
    <gravity>true</gravity>
    <sensor name="imu_sensor" type="imu">
      <always_on>true</always_on>
      <update_rate>250.0</update_rate>
      <visualize>true</visualize>
      <imu>
        <linear_acceleration>
          <x>
            <noise type="gaussian">
              <mean>0.0</mean>
              <stddev>0.00001</stddev>
              <bias_mean>0.0</bias_mean>
              <bias_stddev>0</bias_stddev>
            </noise>
          </x>
          <y>
            <noise type="gaussian">
              <mean>0.0</mean>
              <stddev>0.00001</stddev>
              <bias_mean>0.0</bias_mean>
              <bias_stddev>0</bias_stddev>
            </noise>
          </y>
          <z>
            <noise type="gaussian">
              <mean>0.0</mean>
              <stddev>0.00001</stddev>
              <bias_mean>0.0</bias_mean>
              <bias_stddev>0.0</bias_stddev>
            </noise>
          </z>
        </linear_acceleration>
      </imu>
      <topic>__default_topic__</topic>
      <plugin filename="libgazebo_ros_imu_sensor.so" name="imu_plugin">
        <topicName>go1/trunk_imu</topicName>
        <bodyName>imu_link</bodyName>
        <updateRateHZ>250.0</updateRateHZ>
        <gaussianNoise>0.00001</gaussianNoise>
        <!-- STD dev sqrt of covariance -->
        <xyzOffset>0 0 0</xyzOffset>
        <rpyOffset>0 0 0</rpyOffset>
        <frameName>imu_link</frameName>
      </plugin>
      <pose>0 0 0 0 0 0</pose>
    </sensor>
  </gazebo>
  <!-- Floating-base Joint -->
  <link name="world"/>
  <joint name="floating_base_joint" type="floating">
    <origin rpy="0 0 0" xyz="0 0 0"/>
    <parent link="world"/>
    <child link="base_link"/>
  </joint>
  <link name="base_link"/>
  <joint name="floating_base" type="fixed">
    <origin rpy="0 0 0" xyz="0 0 0"/>
    <parent link="base_link"/>
    <child link="trunk"/>
  </joint>
  <link name="trunk">
    <visual>
      <origin rpy="0 0 0" xyz="0 0 0"/>
      <geometry>
        <mesh filename="package://go1_description/meshes/trunk.dae" scale="1 1 1"/>
      </geometry>
      <!-- <material name="orange"/> -->
    </visual>
    <collision>
      <origin rpy="0 0 0" xyz="0 0 -0.01"/>
      <geometry>
        <box size="0.45 0.1 0.14"/>
      </geometry>
    </collision>
    <inertial>
      <origin rpy="0 0 0" xyz="0.0223 0.002 -0.0005"/>
      <mass value="5.204"/>
      <inertia ixx="0.0168352186" ixy="0.0004636141" ixz="0.0002367952" iyy="0.0656071082" iyz="3.6671e-05" izz="0.0742720659"/>
    </inertial>
  </link>
  <joint name="imu_joint" type="fixed">
    <parent link="trunk"/>
    <child link="imu_link"/>
    <origin rpy="0 0 0" xyz="-0.01592 -0.06659 -0.00617"/>
  </joint>
  <link name="imu_link">
    <inertial>
      <mass value="0.001"/>
      <origin rpy="0 0 0" xyz="0 0 0"/>
      <inertia ixx="0.0001" ixy="0" ixz="0" iyy="0.0001" iyz="0" izz="0.0001"/>
    </inertial>
    <visual>
      <origin rpy="0 0 0" xyz="0 0 0"/>
      <geometry>
        <box size="0.001 0.001 0.001"/>
      </geometry>
      <!-- <material name="red"/> -->
    </visual>
    <collision>
      <origin rpy="0 0 0" xyz="0 0 0"/>
      <geometry>
        <box size=".001 .001 .001"/>
      </geometry>
    </collision>
  </link>
  <joint name="lf_haa_joint" type="revolute">
    <origin rpy="0 0 0" xyz="0.1881 0.04675 0"/>
    <parent link="trunk"/>
    <child link="lf_hip"/>
    <axis xyz="1 0 0"/>
    <dynamics damping="0.0" friction="0.0"/>
    <!-- limit effort="${haa_torque_max}" velocity="${haa_velocity_max}" lower="${haa_min*PI/180.0}" upper="${haa_max*PI/180.0}"/ -->
    <limit effort="23.7" lower="-0.863" upper="0.863" velocity="30.1"/>
  </joint>
  <link name="lf_hip">
    <visual>
      <origin rpy="0 0 0" xyz="0 0 0"/>
      <geometry>
        <mesh filename="package://go1_description/meshes/hip.dae" scale="1 1 1"/>
      </geometry>
      <!-- <material name="orange"/> -->
    </visual>
    <collision>
      <origin rpy="1.5707963267948966 0 0" xyz="0 0 0"/>
      <geometry>
        <cylinder length="0.04" radius="0.046"/>
      </geometry>
    </collision>
    <inertial>
      <origin rpy="0 0 0" xyz="-0.00541 -0.00074 6e-06"/>
      <mass value="0.591"/>
      <inertia ixx="0.000374268192" ixy="3.6844422e-05" ixz="-9.86754e-07" iyy="0.000635923669" iyz="-1.172894e-06" izz="0.000457647394"/>
    </inertial>
  </link>
  <joint name="lf_haa_fixed" type="fixed">
    <origin rpy="0 0 0" xyz="0 0.08 0"/>
    <parent link="lf_hip"/>
    <child link="lf_upperleg_shoulder"/>
  </joint>
  <!-- this link is only for collision -->
  <link name="lf_upperleg_shoulder">
    <collision>
      <origin rpy="1.5707963267948966 0 0" xyz="0 0 0"/>
      <geometry>
        <cylinder length="0.032" radius="0.041"/>
      </geometry>
    </collision>
  </link>
  <!-- haa motor -->
  <joint name="lf_haa_motor_joint" type="fixed">
    <origin rpy="0 0 0" xyz="0.11215 0.04675 0"/>
    <parent link="trunk"/>
    <child link="lf_haa_motor"/>
  </joint>
  <link name="lf_haa_motor">
    <!--visual>
                <origin rpy="0 ${PI/2.0} 0" xyz="0 0 0"/>
                <geometry>
                    <cylinder length="0.02" radius="0.035"/>
                </geometry>
                <material name="green"/>
            </visual>
            <collision>
                <origin rpy="0 ${PI/2.0} 0" xyz="0 0 0"/>
                <geometry>
                    <cylinder length="0.02" radius="0.035"/>
                </geometry>
            </collision -->
    <inertial>
      <origin rpy="0 0 0" xyz="0.0 0.0 0.0"/>
      <mass value="0.089"/>
      <inertia ixx="5.9647e-05" ixy="0.0" ixz="0.0" iyy="0.000111842" iyz="0.0" izz="5.9647e-05"/>
    </inertial>
  </link>
  <joint name="lf_hfe_joint" type="revolute">
    <origin rpy="0 0 0" xyz="0 0.08 0"/>
    <parent link="lf_hip"/>
    <child link="lf_upperleg"/>
    <axis xyz="0 1 0"/>
    <dynamics damping="0.0" friction="0.0"/>
    <!--limit effort="${hfe_torque_max}" velocity="${hfe_velocity_max}" lower="${hfe_min*PI/180.0}" upper="${hfe_max*PI/180.0}"/ -->
    <limit effort="23.7" lower="-0.686" upper="4.501" velocity="30.1"/>
  </joint>
  <!-- hfe motor -->
  <joint name="lf_hfe_motor_joint" type="fixed">
    <origin rpy="0 0 0" xyz="0.0 -0.00015 0"/>
    <parent link="lf_upperleg"/>
    <child link="lf_hfe_motor"/>
  </joint>
  <link name="lf_hfe_motor">
    <!--visual>
                <origin rpy="0 ${PI/2.0} 0" xyz="0 0 0"/>
                <geometry>
                    <cylinder length="0.02" radius="0.035"/>
                </geometry>
                <material name="green"/>
            </visual>
            <collision>
                <origin rpy="0 ${PI/2.0} 0" xyz="0 0 0"/>
                <geometry>
                    <cylinder length="0.02" radius="0.035"/>
                </geometry>
            </collision -->
    <inertial>
      <origin rpy="0 0 0" xyz="0.0 0.0 0.0"/>
      <mass value="0.089"/>
      <inertia ixx="5.9647e-05" ixy="0.0" ixz="0.0" iyy="0.000111842" iyz="0.0" izz="5.9647e-05"/>
    </inertial>
  </link>
  <link name="lf_upperleg">
    <visual>
      <origin rpy="0 0 0" xyz="0 0 0"/>
      <geometry>
        <mesh filename="package://go1_description/meshes/upperleg.dae" scale="1 1 1"/>
      </geometry>
      <!-- <material name="orange"/> -->
    </visual>
    <collision>
      <origin rpy="0 1.5707963267948966 0" xyz="0 0 -0.1065"/>
      <geometry>
        <box size="0.213 0.0245 0.034"/>
      </geometry>
    </collision>
    <inertial>
      <origin rpy="0 0 0" xyz="-0.003468 -0.018947 -0.032736"/>
      <mass value="0.92"/>
      <inertia ixx="0.005851561134" ixy="1.783284e-06" ixz="0.000328291374" iyy="0.005596155105" iyz="2.1430713e-05" izz="0.00107157026"/>
    </inertial>
  </link>
  <joint name="lf_kfe_joint" type="revolute">
    <origin rpy="0 0 0" xyz="0 0 -0.213"/>
    <parent link="lf_upperleg"/>
    <child link="lf_lowerleg"/>
    <axis xyz="0 1 0"/>
    <dynamics damping="0.0" friction="0.0"/>
    <!-- limit effort="${kfe_torque_max}" velocity="${kfe_velocity_max}" lower="${kfe_min*PI/180.0}" upper="${kfe_max*PI/180.0}"/ -->
    <limit effort="35.55" lower="-2.818" upper="-0.888" velocity="20.06"/>
  </joint>
  <link name="lf_lowerleg">
    <visual>
      <origin rpy="0 0 0" xyz="0 0 0"/>
      <geometry>
        <mesh filename="package://go1_description/meshes/lowerleg.dae" scale="1 1 1"/>
      </geometry>
      <!-- <material name="orange"/> -->
    </visual>
    <collision>
      <origin rpy="0 1.5707963267948966 0" xyz="0 0 -0.1065"/>
      <geometry>
        <box size="0.213 0.016 0.016"/>
      </geometry>
    </collision>
    <inertial>
      <origin rpy="0 0 0" xyz="0.006286 0.001307 -0.122269"/>
      <mass value="0.131"/>
      <inertia ixx="0.002939186297" ixy="1.440899e-06" ixz="-0.00010535955" iyy="0.00295576935" iyz="-2.4397752e-05" izz="3.0273372e-05"/>
    </inertial>
  </link>
  <!-- kfe motor -->
  <joint name="lf_kfe_motor_joint" type="fixed">
    <origin rpy="0 0 0" xyz="0.0 -0.03235 0"/>
    <parent link="lf_lowerleg"/>
    <child link="lf_kfe_motor"/>
  </joint>
  <link name="lf_kfe_motor">
    <!--visual>
                <origin rpy="0 ${PI/2.0} 0" xyz="0 0 0"/>
                <geometry>
                    <cylinder length="0.02" radius="0.035"/>
                </geometry>
                <material name="green"/>
            </visual>
            <collision>
                <origin rpy="0 ${PI/2.0} 0" xyz="0 0 0"/>
                <geometry>
                    <cylinder length="0.02" radius="0.035"/>
                </geometry>
            </collision -->
    <inertial>
      <origin rpy="0 0 0" xyz="0.0 0.0 0.0"/>
      <mass value="0.089"/>
      <inertia ixx="5.9647e-05" ixy="0.0" ixz="0.0" iyy="0.000111842" iyz="0.0" izz="5.9647e-05"/>
    </inertial>
  </link>
  <joint name="lf_foot_fixed" type="fixed">
    <origin rpy="0 0 0" xyz="0 0 -0.213"/>
    <parent link="lf_lowerleg"/>
    <child link="lf_foot"/>
  </joint>
  <link name="lf_foot">
    <visual>
      <origin rpy="0 0 0" xyz="0 0 0"/>
      <geometry>
        <sphere radius="0.01"/>
      </geometry>
      <!-- <material name="orange"/> -->
    </visual>
    <collision>
      <origin rpy="0 0 0" xyz="0 0 0"/>
      <geometry>
        <sphere radius="0.02"/>
      </geometry>
    </collision>
    <inertial>
      <mass value="0.06"/>
      <inertia ixx="9.600000000000001e-06" ixy="0.0" ixz="0.0" iyy="9.600000000000001e-06" iyz="0.0" izz="9.600000000000001e-06"/>
    </inertial>
  </link>
  <!-- Hip assembly -->
  <transmission name="lf_haa_trans">
    <type>transmission_interface/SimpleTransmission</type>
    <joint name="lf_haa_joint">
      <hardwareInterface>hardware_interface/EffortJointInterface</hardwareInterface>
    </joint>
    <actuator name="lf_haa_motor">
      <hardwareInterface>hardware_interface/EffortJointInterface</hardwareInterface>
      <mechanicalReduction>1</mechanicalReduction>
    </actuator>
  </transmission>
  <!-- Upper leg -->
  <transmission name="lf_hfe_trans">
    <type>transmission_interface/SimpleTransmission</type>
    <joint name="lf_hfe_joint">
      <hardwareInterface>hardware_interface/EffortJointInterface</hardwareInterface>
    </joint>
    <actuator name="lf_hfe_motor">
      <hardwareInterface>hardware_interface/EffortJointInterface</hardwareInterface>
      <mechanicalReduction>1</mechanicalReduction>
    </actuator>
  </transmission>
  <!-- Lower leg -->
  <transmission name="lf_kfe_trans">
    <type>transmission_interface/SimpleTransmission</type>
    <joint name="lf_kfe_joint">
      <hardwareInterface>hardware_interface/EffortJointInterface</hardwareInterface>
    </joint>
    <actuator name="lf_kfe_motor">
      <hardwareInterface>hardware_interface/EffortJointInterface</hardwareInterface>
      <mechanicalReduction>1</mechanicalReduction>
    </actuator>
  </transmission>
  <!-- UNITREE PLUGINS -->
  <!-- Foot contact >
	    <gazebo reference="${name}_lowerleg">
		    <sensor name="${name}_foot_contact" type="contact">
		    <update_rate>100</update_rate>
		    <plugin name="contactPlugin" filename="libunitreeFootContactPlugin.so"/>
		    <contact>
		        <collision>${name}_lowerleg_fixed_joint_lump__${name}_foot_collision_1</collision>
		    </contact>
		    </sensor>
	    </gazebo>


	    <Visualization of Foot contacts. >
	    <gazebo reference="${name}_foot">
		    <visual>
		        <plugin name="drawForcePlugin" filename="libunitreeDrawForcePlugin.so">
		            <topicName>${name}_foot_contact</topicName>
		        </plugin>
		    </visual>
	    </gazebo-->
  <gazebo reference="lf_upperleg">
    <kp>1000000.0</kp>
    <kd>100.0</kd>
    <mu1>1.5</mu1>
    <mu2>1.5</mu2>
    <fdir1>1 0 0</fdir1>
    <maxVel>1.0</maxVel>
    <minDepth>0.00</minDepth>
  </gazebo>
  <gazebo reference="lf_lowerleg">
    <kp>1000000.0</kp>
    <kd>100.0</kd>
    <mu1>1.0</mu1>
    <mu2>1.0</mu2>
    <maxVel>1.0</maxVel>
    <maxContacts>1</maxContacts>
  </gazebo>
  <gazebo reference="lf_foot">
    <kp>1000000.0</kp>
    <kd>100.0</kd>
    <mu1>1.0</mu1>
    <mu2>1.0</mu2>
    <maxVel>1.0</maxVel>
    <maxContacts>1</maxContacts>
    <material>Gazebo/Black</material>
  </gazebo>
  <joint name="rf_haa_joint" type="revolute">
    <origin rpy="0 0 0" xyz="0.1881 -0.04675 0"/>
    <parent link="trunk"/>
    <child link="rf_hip"/>
    <axis xyz="1 0 0"/>
    <dynamics damping="0.0" friction="0.0"/>
    <!-- limit effort="${haa_torque_max}" velocity="${haa_velocity_max}" lower="${-haa_max*PI/180.0}" upper="${-haa_min*PI/180.0}"/ -->
    <limit effort="23.7" lower="-0.863" upper="0.863" velocity="30.1"/>
  </joint>
  <link name="rf_hip">
    <visual>
      <origin rpy="3.141592653589793 0 0" xyz="0 0 0"/>
      <geometry>
        <mesh filename="package://go1_description/meshes/hip.dae" scale="1 1 1"/>
      </geometry>
      <!-- <material name="orange"/> -->
    </visual>
    <collision>
      <origin rpy="1.5707963267948966 0 0" xyz="0 0 0"/>
      <geometry>
        <cylinder length="0.04" radius="0.046"/>
      </geometry>
    </collision>
    <inertial>
      <origin rpy="0 0 0" xyz="-0.00541 0.00074 6e-06"/>
      <mass value="0.591"/>
      <inertia ixx="0.000374268192" ixy="-3.6844422e-05" ixz="-9.86754e-07" iyy="0.000635923669" iyz="1.172894e-06" izz="0.000457647394"/>
    </inertial>
  </link>
  <joint name="rf_haa_fixed" type="fixed">
    <origin rpy="0 0 0" xyz="0 -0.08 0"/>
    <parent link="rf_hip"/>
    <child link="rf_upperleg_shoulder"/>
  </joint>
  <!-- this link is only for collision -->
  <link name="rf_upperleg_shoulder">
    <collision>
      <origin rpy="1.5707963267948966 0 0" xyz="0 0 0"/>
      <geometry>
        <cylinder length="0.032" radius="0.041"/>
      </geometry>
    </collision>
  </link>
  <!-- haa motor -->
  <joint name="rf_haa_motor_joint" type="fixed">
    <origin rpy="0 0 0" xyz="0.11215 -0.04675 0"/>
    <parent link="trunk"/>
    <child link="rf_haa_motor"/>
  </joint>
  <link name="rf_haa_motor">
    <!--visual>
                <origin rpy="0 ${PI/2.0} 0" xyz="0 0 0"/>
                <geometry>
                    <cylinder length="0.02" radius="0.035"/>
                </geometry>
                <material name="green"/>
            </visual>
            <collision>
                <origin rpy="0 ${PI/2.0} 0" xyz="0 0 0"/>
                <geometry>
                    <cylinder length="0.02" radius="0.035"/>
                </geometry>
            </collision -->
    <inertial>
      <origin rpy="0 0 0" xyz="0.0 0.0 0.0"/>
      <mass value="0.089"/>
      <inertia ixx="5.9647e-05" ixy="0.0" ixz="0.0" iyy="0.000111842" iyz="0.0" izz="5.9647e-05"/>
    </inertial>
  </link>
  <joint name="rf_hfe_joint" type="revolute">
    <origin rpy="0 0 0" xyz="0 -0.08 0"/>
    <parent link="rf_hip"/>
    <child link="rf_upperleg"/>
    <axis xyz="0 1 0"/>
    <dynamics damping="0.0" friction="0.0"/>
    <!--limit effort="${hfe_torque_max}" velocity="${hfe_velocity_max}" lower="${hfe_min*PI/180.0}" upper="${hfe_max*PI/180.0}"/ -->
    <limit effort="23.7" lower="-0.686" upper="4.501" velocity="30.1"/>
  </joint>
  <!-- hfe motor -->
  <joint name="rf_hfe_motor_joint" type="fixed">
    <origin rpy="0 0 0" xyz="0.0 0.00015 0"/>
    <parent link="rf_upperleg"/>
    <child link="rf_hfe_motor"/>
  </joint>
  <link name="rf_hfe_motor">
    <!--visual>
                <origin rpy="0 ${PI/2.0} 0" xyz="0 0 0"/>
                <geometry>
                    <cylinder length="0.02" radius="0.035"/>
                </geometry>
                <material name="green"/>
            </visual>
            <collision>
                <origin rpy="0 ${PI/2.0} 0" xyz="0 0 0"/>
                <geometry>
                    <cylinder length="0.02" radius="0.035"/>
                </geometry>
            </collision -->
    <inertial>
      <origin rpy="0 0 0" xyz="0.0 0.0 0.0"/>
      <mass value="0.089"/>
      <inertia ixx="5.9647e-05" ixy="0.0" ixz="0.0" iyy="0.000111842" iyz="0.0" izz="5.9647e-05"/>
    </inertial>
  </link>
  <link name="rf_upperleg">
    <visual>
      <origin rpy="0 0 0" xyz="0 0 0"/>
      <geometry>
        <mesh filename="package://go1_description/meshes/upperleg_mirror.dae" scale="1 1 1"/>
      </geometry>
      <!-- <material name="orange"/> -->
    </visual>
    <collision>
      <origin rpy="0 1.5707963267948966 0" xyz="0 0 -0.1065"/>
      <geometry>
        <box size="0.213 0.0245 0.034"/>
      </geometry>
    </collision>
    <inertial>
      <origin rpy="0 0 0" xyz="-0.003468 0.018947 -0.032736"/>
      <mass value="0.92"/>
      <inertia ixx="0.005851561134" ixy="-1.783284e-06" ixz="0.000328291374" iyy="0.005596155105" iyz="-2.1430713e-05" izz="0.00107157026"/>
    </inertial>
  </link>
  <joint name="rf_kfe_joint" type="revolute">
    <origin rpy="0 0 0" xyz="0 0 -0.213"/>
    <parent link="rf_upperleg"/>
    <child link="rf_lowerleg"/>
    <axis xyz="0 1 0"/>
    <dynamics damping="0.0" friction="0.0"/>
    <!-- limit effort="${kfe_torque_max}" velocity="${kfe_velocity_max}" lower="${kfe_min*PI/180.0}" upper="${kfe_max*PI/180.0}"/ -->
    <limit effort="35.55" lower="-2.818" upper="-0.888" velocity="20.06"/>
  </joint>
  <link name="rf_lowerleg">
    <visual>
      <origin rpy="0 0 0" xyz="0 0 0"/>
      <geometry>
        <mesh filename="package://go1_description/meshes/lowerleg.dae" scale="1 1 1"/>
      </geometry>
      <!-- <material name="orange"/> -->
    </visual>
    <collision>
      <origin rpy="0 1.5707963267948966 0" xyz="0 0 -0.1065"/>
      <geometry>
        <box size="0.213 0.016 0.016"/>
      </geometry>
    </collision>
    <inertial>
      <origin rpy="0 0 0" xyz="0.006286 0.001307 -0.122269"/>
      <mass value="0.131"/>
      <inertia ixx="0.002939186297" ixy="1.440899e-06" ixz="-0.00010535955" iyy="0.00295576935" iyz="-2.4397752e-05" izz="3.0273372e-05"/>
    </inertial>
  </link>
  <!-- kfe motor -->
  <joint name="rf_kfe_motor_joint" type="fixed">
    <origin rpy="0 0 0" xyz="0.0 0.03235 0"/>
    <parent link="rf_lowerleg"/>
    <child link="rf_kfe_motor"/>
  </joint>
  <link name="rf_kfe_motor">
    <!--visual>
                <origin rpy="0 ${PI/2.0} 0" xyz="0 0 0"/>
                <geometry>
                    <cylinder length="0.02" radius="0.035"/>
                </geometry>
                <material name="green"/>
            </visual>
            <collision>
                <origin rpy="0 ${PI/2.0} 0" xyz="0 0 0"/>
                <geometry>
                    <cylinder length="0.02" radius="0.035"/>
                </geometry>
            </collision -->
    <inertial>
      <origin rpy="0 0 0" xyz="0.0 0.0 0.0"/>
      <mass value="0.089"/>
      <inertia ixx="5.9647e-05" ixy="0.0" ixz="0.0" iyy="0.000111842" iyz="0.0" izz="5.9647e-05"/>
    </inertial>
  </link>
  <joint name="rf_foot_fixed" type="fixed">
    <origin rpy="0 0 0" xyz="0 0 -0.213"/>
    <parent link="rf_lowerleg"/>
    <child link="rf_foot"/>
  </joint>
  <link name="rf_foot">
    <visual>
      <origin rpy="0 0 0" xyz="0 0 0"/>
      <geometry>
        <sphere radius="0.01"/>
      </geometry>
      <!-- <material name="orange"/> -->
    </visual>
    <collision>
      <origin rpy="0 0 0" xyz="0 0 0"/>
      <geometry>
        <sphere radius="0.02"/>
      </geometry>
    </collision>
    <inertial>
      <mass value="0.06"/>
      <inertia ixx="9.600000000000001e-06" ixy="0.0" ixz="0.0" iyy="9.600000000000001e-06" iyz="0.0" izz="9.600000000000001e-06"/>
    </inertial>
  </link>
  <!-- Hip assembly -->
  <transmission name="rf_haa_trans">
    <type>transmission_interface/SimpleTransmission</type>
    <joint name="rf_haa_joint">
      <hardwareInterface>hardware_interface/EffortJointInterface</hardwareInterface>
    </joint>
    <actuator name="rf_haa_motor">
      <hardwareInterface>hardware_interface/EffortJointInterface</hardwareInterface>
      <mechanicalReduction>1</mechanicalReduction>
    </actuator>
  </transmission>
  <!-- Upper leg -->
  <transmission name="rf_hfe_trans">
    <type>transmission_interface/SimpleTransmission</type>
    <joint name="rf_hfe_joint">
      <hardwareInterface>hardware_interface/EffortJointInterface</hardwareInterface>
    </joint>
    <actuator name="rf_hfe_motor">
      <hardwareInterface>hardware_interface/EffortJointInterface</hardwareInterface>
      <mechanicalReduction>1</mechanicalReduction>
    </actuator>
  </transmission>
  <!-- Lower leg -->
  <transmission name="rf_kfe_trans">
    <type>transmission_interface/SimpleTransmission</type>
    <joint name="rf_kfe_joint">
      <hardwareInterface>hardware_interface/EffortJointInterface</hardwareInterface>
    </joint>
    <actuator name="rf_kfe_motor">
      <hardwareInterface>hardware_interface/EffortJointInterface</hardwareInterface>
      <mechanicalReduction>1</mechanicalReduction>
    </actuator>
  </transmission>
  <!-- UNITREE PLUGINS -->
  <!-- Foot contact >
	    <gazebo reference="${name}_lowerleg">
		    <sensor name="${name}_foot_contact" type="contact">
		    <update_rate>100</update_rate>
		    <plugin name="contactPlugin" filename="libunitreeFootContactPlugin.so"/>
		    <contact>
		        <collision>${name}_lowerleg_fixed_joint_lump__${name}_foot_collision_1</collision>
		    </contact>
		    </sensor>
	    </gazebo>


	    <Visualization of Foot contacts. >
	    <gazebo reference="${name}_foot">
		    <visual>
		        <plugin name="drawForcePlugin" filename="libunitreeDrawForcePlugin.so">
		            <topicName>${name}_foot_contact</topicName>
		        </plugin>
		    </visual>
	    </gazebo-->
  <gazebo reference="rf_upperleg">
    <kp>1000000.0</kp>
    <kd>100.0</kd>
    <mu1>1.5</mu1>
    <mu2>1.5</mu2>
    <fdir1>1 0 0</fdir1>
    <maxVel>1.0</maxVel>
    <minDepth>0.00</minDepth>
  </gazebo>
  <gazebo reference="rf_lowerleg">
    <kp>1000000.0</kp>
    <kd>100.0</kd>
    <mu1>1.0</mu1>
    <mu2>1.0</mu2>
    <maxVel>1.0</maxVel>
    <maxContacts>1</maxContacts>
  </gazebo>
  <gazebo reference="rf_foot">
    <kp>1000000.0</kp>
    <kd>100.0</kd>
    <mu1>1.0</mu1>
    <mu2>1.0</mu2>
    <maxVel>1.0</maxVel>
    <maxContacts>1</maxContacts>
    <material>Gazebo/Black</material>
  </gazebo>
  <joint name="lh_haa_joint" type="revolute">
    <origin rpy="0 0 0" xyz="-0.1881 0.04675 0"/>
    <parent link="trunk"/>
    <child link="lh_hip"/>
    <axis xyz="1 0 0"/>
    <dynamics damping="0.0" friction="0.0"/>
    <!-- limit effort="${haa_torque_max}" velocity="${haa_velocity_max}" lower="${haa_min*PI/180.0}" upper="${haa_max*PI/180.0}"/ -->
    <limit effort="23.7" lower="-0.863" upper="0.863" velocity="30.1"/>
  </joint>
  <link name="lh_hip">
    <visual>
      <origin rpy="0 3.141592653589793 0" xyz="0 0 0"/>
      <geometry>
        <mesh filename="package://go1_description/meshes/hip.dae" scale="1 1 1"/>
      </geometry>
      <!-- <material name="orange"/> -->
    </visual>
    <collision>
      <origin rpy="1.5707963267948966 0 0" xyz="0 0 0"/>
      <geometry>
        <cylinder length="0.04" radius="0.046"/>
      </geometry>
    </collision>
    <inertial>
      <origin rpy="0 0 0" xyz="0.00541 -0.00074 6e-06"/>
      <mass value="0.591"/>
      <inertia ixx="0.000374268192" ixy="-3.6844422e-05" ixz="9.86754e-07" iyy="0.000635923669" iyz="-1.172894e-06" izz="0.000457647394"/>
    </inertial>
  </link>
  <joint name="lh_haa_fixed" type="fixed">
    <origin rpy="0 0 0" xyz="0 0.08 0"/>
    <parent link="lh_hip"/>
    <child link="lh_upperleg_shoulder"/>
  </joint>
  <!-- this link is only for collision -->
  <link name="lh_upperleg_shoulder">
    <collision>
      <origin rpy="1.5707963267948966 0 0" xyz="0 0 0"/>
      <geometry>
        <cylinder length="0.032" radius="0.041"/>
      </geometry>
    </collision>
  </link>
  <!-- haa motor -->
  <joint name="lh_haa_motor_joint" type="fixed">
    <origin rpy="0 0 0" xyz="-0.11215 0.04675 0"/>
    <parent link="trunk"/>
    <child link="lh_haa_motor"/>
  </joint>
  <link name="lh_haa_motor">
    <!--visual>
                <origin rpy="0 ${PI/2.0} 0" xyz="0 0 0"/>
                <geometry>
                    <cylinder length="0.02" radius="0.035"/>
                </geometry>
                <material name="green"/>
            </visual>
            <collision>
                <origin rpy="0 ${PI/2.0} 0" xyz="0 0 0"/>
                <geometry>
                    <cylinder length="0.02" radius="0.035"/>
                </geometry>
            </collision -->
    <inertial>
      <origin rpy="0 0 0" xyz="0.0 0.0 0.0"/>
      <mass value="0.089"/>
      <inertia ixx="5.9647e-05" ixy="0.0" ixz="0.0" iyy="0.000111842" iyz="0.0" izz="5.9647e-05"/>
    </inertial>
  </link>
  <joint name="lh_hfe_joint" type="revolute">
    <origin rpy="0 0 0" xyz="0 0.08 0"/>
    <parent link="lh_hip"/>
    <child link="lh_upperleg"/>
    <axis xyz="0 1 0"/>
    <dynamics damping="0.0" friction="0.0"/>
    <!--limit effort="${hfe_torque_max}" velocity="${hfe_velocity_max}" lower="${hfe_min*PI/180.0}" upper="${hfe_max*PI/180.0}"/ -->
    <limit effort="23.7" lower="-0.686" upper="4.501" velocity="30.1"/>
  </joint>
  <!-- hfe motor -->
  <joint name="lh_hfe_motor_joint" type="fixed">
    <origin rpy="0 0 0" xyz="-0.0 -0.00015 0"/>
    <parent link="lh_upperleg"/>
    <child link="lh_hfe_motor"/>
  </joint>
  <link name="lh_hfe_motor">
    <!--visual>
                <origin rpy="0 ${PI/2.0} 0" xyz="0 0 0"/>
                <geometry>
                    <cylinder length="0.02" radius="0.035"/>
                </geometry>
                <material name="green"/>
            </visual>
            <collision>
                <origin rpy="0 ${PI/2.0} 0" xyz="0 0 0"/>
                <geometry>
                    <cylinder length="0.02" radius="0.035"/>
                </geometry>
            </collision -->
    <inertial>
      <origin rpy="0 0 0" xyz="0.0 0.0 0.0"/>
      <mass value="0.089"/>
      <inertia ixx="5.9647e-05" ixy="0.0" ixz="0.0" iyy="0.000111842" iyz="0.0" izz="5.9647e-05"/>
    </inertial>
  </link>
  <link name="lh_upperleg">
    <visual>
      <origin rpy="0 0 0" xyz="0 0 0"/>
      <geometry>
        <mesh filename="package://go1_description/meshes/upperleg.dae" scale="1 1 1"/>
      </geometry>
      <!-- <material name="orange"/> -->
    </visual>
    <collision>
      <origin rpy="0 1.5707963267948966 0" xyz="0 0 -0.1065"/>
      <geometry>
        <box size="0.213 0.0245 0.034"/>
      </geometry>
    </collision>
    <inertial>
      <origin rpy="0 0 0" xyz="-0.003468 -0.018947 -0.032736"/>
      <mass value="0.92"/>
      <inertia ixx="0.005851561134" ixy="1.783284e-06" ixz="0.000328291374" iyy="0.005596155105" iyz="2.1430713e-05" izz="0.00107157026"/>
    </inertial>
  </link>
  <joint name="lh_kfe_joint" type="revolute">
    <origin rpy="0 0 0" xyz="0 0 -0.213"/>
    <parent link="lh_upperleg"/>
    <child link="lh_lowerleg"/>
    <axis xyz="0 1 0"/>
    <dynamics damping="0.0" friction="0.0"/>
    <!-- limit effort="${kfe_torque_max}" velocity="${kfe_velocity_max}" lower="${kfe_min*PI/180.0}" upper="${kfe_max*PI/180.0}"/ -->
    <limit effort="35.55" lower="-2.818" upper="-0.888" velocity="20.06"/>
  </joint>
  <link name="lh_lowerleg">
    <visual>
      <origin rpy="0 0 0" xyz="0 0 0"/>
      <geometry>
        <mesh filename="package://go1_description/meshes/lowerleg.dae" scale="1 1 1"/>
      </geometry>
      <!-- <material name="orange"/> -->
    </visual>
    <collision>
      <origin rpy="0 1.5707963267948966 0" xyz="0 0 -0.1065"/>
      <geometry>
        <box size="0.213 0.016 0.016"/>
      </geometry>
    </collision>
    <inertial>
      <origin rpy="0 0 0" xyz="0.006286 0.001307 -0.122269"/>
      <mass value="0.131"/>
      <inertia ixx="0.002939186297" ixy="1.440899e-06" ixz="-0.00010535955" iyy="0.00295576935" iyz="-2.4397752e-05" izz="3.0273372e-05"/>
    </inertial>
  </link>
  <!-- kfe motor -->
  <joint name="lh_kfe_motor_joint" type="fixed">
    <origin rpy="0 0 0" xyz="-0.0 -0.03235 0"/>
    <parent link="lh_lowerleg"/>
    <child link="lh_kfe_motor"/>
  </joint>
  <link name="lh_kfe_motor">
    <!--visual>
                <origin rpy="0 ${PI/2.0} 0" xyz="0 0 0"/>
                <geometry>
                    <cylinder length="0.02" radius="0.035"/>
                </geometry>
                <material name="green"/>
            </visual>
            <collision>
                <origin rpy="0 ${PI/2.0} 0" xyz="0 0 0"/>
                <geometry>
                    <cylinder length="0.02" radius="0.035"/>
                </geometry>
            </collision -->
    <inertial>
      <origin rpy="0 0 0" xyz="0.0 0.0 0.0"/>
      <mass value="0.089"/>
      <inertia ixx="5.9647e-05" ixy="0.0" ixz="0.0" iyy="0.000111842" iyz="0.0" izz="5.9647e-05"/>
    </inertial>
  </link>
  <joint name="lh_foot_fixed" type="fixed">
    <origin rpy="0 0 0" xyz="0 0 -0.213"/>
    <parent link="lh_lowerleg"/>
    <child link="lh_foot"/>
  </joint>
  <link name="lh_foot">
    <visual>
      <origin rpy="0 0 0" xyz="0 0 0"/>
      <geometry>
        <sphere radius="0.01"/>
      </geometry>
      <!-- <material name="orange"/> -->
    </visual>
    <collision>
      <origin rpy="0 0 0" xyz="0 0 0"/>
      <geometry>
        <sphere radius="0.02"/>
      </geometry>
    </collision>
    <inertial>
      <mass value="0.06"/>
      <inertia ixx="9.600000000000001e-06" ixy="0.0" ixz="0.0" iyy="9.600000000000001e-06" iyz="0.0" izz="9.600000000000001e-06"/>
    </inertial>
  </link>
  <!-- Hip assembly -->
  <transmission name="lh_haa_trans">
    <type>transmission_interface/SimpleTransmission</type>
    <joint name="lh_haa_joint">
      <hardwareInterface>hardware_interface/EffortJointInterface</hardwareInterface>
    </joint>
    <actuator name="lh_haa_motor">
      <hardwareInterface>hardware_interface/EffortJointInterface</hardwareInterface>
      <mechanicalReduction>1</mechanicalReduction>
    </actuator>
  </transmission>
  <!-- Upper leg -->
  <transmission name="lh_hfe_trans">
    <type>transmission_interface/SimpleTransmission</type>
    <joint name="lh_hfe_joint">
      <hardwareInterface>hardware_interface/EffortJointInterface</hardwareInterface>
    </joint>
    <actuator name="lh_hfe_motor">
      <hardwareInterface>hardware_interface/EffortJointInterface</hardwareInterface>
      <mechanicalReduction>1</mechanicalReduction>
    </actuator>
  </transmission>
  <!-- Lower leg -->
  <transmission name="lh_kfe_trans">
    <type>transmission_interface/SimpleTransmission</type>
    <joint name="lh_kfe_joint">
      <hardwareInterface>hardware_interface/EffortJointInterface</hardwareInterface>
    </joint>
    <actuator name="lh_kfe_motor">
      <hardwareInterface>hardware_interface/EffortJointInterface</hardwareInterface>
      <mechanicalReduction>1</mechanicalReduction>
    </actuator>
  </transmission>
  <!-- UNITREE PLUGINS -->
  <!-- Foot contact >
	    <gazebo reference="${name}_lowerleg">
		    <sensor name="${name}_foot_contact" type="contact">
		    <update_rate>100</update_rate>
		    <plugin name="contactPlugin" filename="libunitreeFootContactPlugin.so"/>
		    <contact>
		        <collision>${name}_lowerleg_fixed_joint_lump__${name}_foot_collision_1</collision>
		    </contact>
		    </sensor>
	    </gazebo>


	    <Visualization of Foot contacts. >
	    <gazebo reference="${name}_foot">
		    <visual>
		        <plugin name="drawForcePlugin" filename="libunitreeDrawForcePlugin.so">
		            <topicName>${name}_foot_contact</topicName>
		        </plugin>
		    </visual>
	    </gazebo-->
  <gazebo reference="lh_upperleg">
    <kp>1000000.0</kp>
    <kd>100.0</kd>
    <mu1>1.5</mu1>
    <mu2>1.5</mu2>
    <fdir1>1 0 0</fdir1>
    <maxVel>1.0</maxVel>
    <minDepth>0.00</minDepth>
  </gazebo>
  <gazebo reference="lh_lowerleg">
    <kp>1000000.0</kp>
    <kd>100.0</kd>
    <mu1>1.0</mu1>
    <mu2>1.0</mu2>
    <maxVel>1.0</maxVel>
    <maxContacts>1</maxContacts>
  </gazebo>
  <gazebo reference="lh_foot">
    <kp>1000000.0</kp>
    <kd>100.0</kd>
    <mu1>1.0</mu1>
    <mu2>1.0</mu2>
    <maxVel>1.0</maxVel>
    <maxContacts>1</maxContacts>
    <material>Gazebo/Black</material>
  </gazebo>
  <joint name="rh_haa_joint" type="revolute">
    <origin rpy="0 0 0" xyz="-0.1881 -0.04675 0"/>
    <parent link="trunk"/>
    <child link="rh_hip"/>
    <axis xyz="1 0 0"/>
    <dynamics damping="0.0" friction="0.0"/>
    <!-- limit effort="${haa_torque_max}" velocity="${haa_velocity_max}" lower="${-haa_max*PI/180.0}" upper="${-haa_min*PI/180.0}"/ -->
    <limit effort="23.7" lower="-0.863" upper="0.863" velocity="30.1"/>
  </joint>
  <link name="rh_hip">
    <visual>
      <origin rpy="3.141592653589793 3.141592653589793 0" xyz="0 0 0"/>
      <geometry>
        <mesh filename="package://go1_description/meshes/hip.dae" scale="1 1 1"/>
      </geometry>
      <!-- <material name="orange"/> -->
    </visual>
    <collision>
      <origin rpy="1.5707963267948966 0 0" xyz="0 0 0"/>
      <geometry>
        <cylinder length="0.04" radius="0.046"/>
      </geometry>
    </collision>
    <inertial>
      <origin rpy="0 0 0" xyz="0.00541 0.00074 6e-06"/>
      <mass value="0.591"/>
      <inertia ixx="0.000374268192" ixy="3.6844422e-05" ixz="9.86754e-07" iyy="0.000635923669" iyz="1.172894e-06" izz="0.000457647394"/>
    </inertial>
  </link>
  <joint name="rh_haa_fixed" type="fixed">
    <origin rpy="0 0 0" xyz="0 -0.08 0"/>
    <parent link="rh_hip"/>
    <child link="rh_upperleg_shoulder"/>
  </joint>
  <!-- this link is only for collision -->
  <link name="rh_upperleg_shoulder">
    <collision>
      <origin rpy="1.5707963267948966 0 0" xyz="0 0 0"/>
      <geometry>
        <cylinder length="0.032" radius="0.041"/>
      </geometry>
    </collision>
  </link>
  <!-- haa motor -->
  <joint name="rh_haa_motor_joint" type="fixed">
    <origin rpy="0 0 0" xyz="-0.11215 -0.04675 0"/>
    <parent link="trunk"/>
    <child link="rh_haa_motor"/>
  </joint>
  <link name="rh_haa_motor">
    <!--visual>
                <origin rpy="0 ${PI/2.0} 0" xyz="0 0 0"/>
                <geometry>
                    <cylinder length="0.02" radius="0.035"/>
                </geometry>
                <material name="green"/>
            </visual>
            <collision>
                <origin rpy="0 ${PI/2.0} 0" xyz="0 0 0"/>
                <geometry>
                    <cylinder length="0.02" radius="0.035"/>
                </geometry>
            </collision -->
    <inertial>
      <origin rpy="0 0 0" xyz="0.0 0.0 0.0"/>
      <mass value="0.089"/>
      <inertia ixx="5.9647e-05" ixy="0.0" ixz="0.0" iyy="0.000111842" iyz="0.0" izz="5.9647e-05"/>
    </inertial>
  </link>
  <joint name="rh_hfe_joint" type="revolute">
    <origin rpy="0 0 0" xyz="0 -0.08 0"/>
    <parent link="rh_hip"/>
    <child link="rh_upperleg"/>
    <axis xyz="0 1 0"/>
    <dynamics damping="0.0" friction="0.0"/>
    <!--limit effort="${hfe_torque_max}" velocity="${hfe_velocity_max}" lower="${hfe_min*PI/180.0}" upper="${hfe_max*PI/180.0}"/ -->
    <limit effort="23.7" lower="-0.686" upper="4.501" velocity="30.1"/>
  </joint>
  <!-- hfe motor -->
  <joint name="rh_hfe_motor_joint" type="fixed">
    <origin rpy="0 0 0" xyz="-0.0 0.00015 0"/>
    <parent link="rh_upperleg"/>
    <child link="rh_hfe_motor"/>
  </joint>
  <link name="rh_hfe_motor">
    <!--visual>
                <origin rpy="0 ${PI/2.0} 0" xyz="0 0 0"/>
                <geometry>
                    <cylinder length="0.02" radius="0.035"/>
                </geometry>
                <material name="green"/>
            </visual>
            <collision>
                <origin rpy="0 ${PI/2.0} 0" xyz="0 0 0"/>
                <geometry>
                    <cylinder length="0.02" radius="0.035"/>
                </geometry>
            </collision -->
    <inertial>
      <origin rpy="0 0 0" xyz="0.0 0.0 0.0"/>
      <mass value="0.089"/>
      <inertia ixx="5.9647e-05" ixy="0.0" ixz="0.0" iyy="0.000111842" iyz="0.0" izz="5.9647e-05"/>
    </inertial>
  </link>
  <link name="rh_upperleg">
    <visual>
      <origin rpy="0 0 0" xyz="0 0 0"/>
      <geometry>
        <mesh filename="package://go1_description/meshes/upperleg_mirror.dae" scale="1 1 1"/>
      </geometry>
      <!-- <material name="orange"/> -->
    </visual>
    <collision>
      <origin rpy="0 1.5707963267948966 0" xyz="0 0 -0.1065"/>
      <geometry>
        <box size="0.213 0.0245 0.034"/>
      </geometry>
    </collision>
    <inertial>
      <origin rpy="0 0 0" xyz="-0.003468 0.018947 -0.032736"/>
      <mass value="0.92"/>
      <inertia ixx="0.005851561134" ixy="-1.783284e-06" ixz="0.000328291374" iyy="0.005596155105" iyz="-2.1430713e-05" izz="0.00107157026"/>
    </inertial>
  </link>
  <joint name="rh_kfe_joint" type="revolute">
    <origin rpy="0 0 0" xyz="0 0 -0.213"/>
    <parent link="rh_upperleg"/>
    <child link="rh_lowerleg"/>
    <axis xyz="0 1 0"/>
    <dynamics damping="0.0" friction="0.0"/>
    <!-- limit effort="${kfe_torque_max}" velocity="${kfe_velocity_max}" lower="${kfe_min*PI/180.0}" upper="${kfe_max*PI/180.0}"/ -->
    <limit effort="35.55" lower="-2.818" upper="-0.888" velocity="20.06"/>
  </joint>
  <link name="rh_lowerleg">
    <visual>
      <origin rpy="0 0 0" xyz="0 0 0"/>
      <geometry>
        <mesh filename="package://go1_description/meshes/lowerleg.dae" scale="1 1 1"/>
      </geometry>
      <!-- <material name="orange"/> -->
    </visual>
    <collision>
      <origin rpy="0 1.5707963267948966 0" xyz="0 0 -0.1065"/>
      <geometry>
        <box size="0.213 0.016 0.016"/>
      </geometry>
    </collision>
    <inertial>
      <origin rpy="0 0 0" xyz="0.006286 0.001307 -0.122269"/>
      <mass value="0.131"/>
      <inertia ixx="0.002939186297" ixy="1.440899e-06" ixz="-0.00010535955" iyy="0.00295576935" iyz="-2.4397752e-05" izz="3.0273372e-05"/>
    </inertial>
  </link>
  <!-- kfe motor -->
  <joint name="rh_kfe_motor_joint" type="fixed">
    <origin rpy="0 0 0" xyz="-0.0 0.03235 0"/>
    <parent link="rh_lowerleg"/>
    <child link="rh_kfe_motor"/>
  </joint>
  <link name="rh_kfe_motor">
    <!--visual>
                <origin rpy="0 ${PI/2.0} 0" xyz="0 0 0"/>
                <geometry>
                    <cylinder length="0.02" radius="0.035"/>
                </geometry>
                <material name="green"/>
            </visual>
            <collision>
                <origin rpy="0 ${PI/2.0} 0" xyz="0 0 0"/>
                <geometry>
                    <cylinder length="0.02" radius="0.035"/>
                </geometry>
            </collision -->
    <inertial>
      <origin rpy="0 0 0" xyz="0.0 0.0 0.0"/>
      <mass value="0.089"/>
      <inertia ixx="5.9647e-05" ixy="0.0" ixz="0.0" iyy="0.000111842" iyz="0.0" izz="5.9647e-05"/>
    </inertial>
  </link>
  <joint name="rh_foot_fixed" type="fixed">
    <origin rpy="0 0 0" xyz="0 0 -0.213"/>
    <parent link="rh_lowerleg"/>
    <child link="rh_foot"/>
  </joint>
  <link name="rh_foot">
    <visual>
      <origin rpy="0 0 0" xyz="0 0 0"/>
      <geometry>
        <sphere radius="0.01"/>
      </geometry>
      <!-- <material name="orange"/> -->
    </visual>
    <collision>
      <origin rpy="0 0 0" xyz="0 0 0"/>
      <geometry>
        <sphere radius="0.02"/>
      </geometry>
    </collision>
    <inertial>
      <mass value="0.06"/>
      <inertia ixx="9.600000000000001e-06" ixy="0.0" ixz="0.0" iyy="9.600000000000001e-06" iyz="0.0" izz="9.600000000000001e-06"/>
    </inertial>
  </link>
  <!-- Hip assembly -->
  <transmission name="rh_haa_trans">
    <type>transmission_interface/SimpleTransmission</type>
    <joint name="rh_haa_joint">
      <hardwareInterface>hardware_interface/EffortJointInterface</hardwareInterface>
    </joint>
    <actuator name="rh_haa_motor">
      <hardwareInterface>hardware_interface/EffortJointInterface</hardwareInterface>
      <mechanicalReduction>1</mechanicalReduction>
    </actuator>
  </transmission>
  <!-- Upper leg -->
  <transmission name="rh_hfe_trans">
    <type>transmission_interface/SimpleTransmission</type>
    <joint name="rh_hfe_joint">
      <hardwareInterface>hardware_interface/EffortJointInterface</hardwareInterface>
    </joint>
    <actuator name="rh_hfe_motor">
      <hardwareInterface>hardware_interface/EffortJointInterface</hardwareInterface>
      <mechanicalReduction>1</mechanicalReduction>
    </actuator>
  </transmission>
  <!-- Lower leg -->
  <transmission name="rh_kfe_trans">
    <type>transmission_interface/SimpleTransmission</type>
    <joint name="rh_kfe_joint">
      <hardwareInterface>hardware_interface/EffortJointInterface</hardwareInterface>
    </joint>
    <actuator name="rh_kfe_motor">
      <hardwareInterface>hardware_interface/EffortJointInterface</hardwareInterface>
      <mechanicalReduction>1</mechanicalReduction>
    </actuator>
  </transmission>
  <!-- UNITREE PLUGINS -->
  <!-- Foot contact >
	    <gazebo reference="${name}_lowerleg">
		    <sensor name="${name}_foot_contact" type="contact">
		    <update_rate>100</update_rate>
		    <plugin name="contactPlugin" filename="libunitreeFootContactPlugin.so"/>
		    <contact>
		        <collision>${name}_lowerleg_fixed_joint_lump__${name}_foot_collision_1</collision>
		    </contact>
		    </sensor>
	    </gazebo>


	    <Visualization of Foot contacts. >
	    <gazebo reference="${name}_foot">
		    <visual>
		        <plugin name="drawForcePlugin" filename="libunitreeDrawForcePlugin.so">
		            <topicName>${name}_foot_contact</topicName>
		        </plugin>
		    </visual>
	    </gazebo-->
  <gazebo reference="rh_upperleg">
    <kp>1000000.0</kp>
    <kd>100.0</kd>
    <mu1>1.5</mu1>
    <mu2>1.5</mu2>
    <fdir1>1 0 0</fdir1>
    <maxVel>1.0</maxVel>
    <minDepth>0.00</minDepth>
  </gazebo>
  <gazebo reference="rh_lowerleg">
    <kp>1000000.0</kp>
    <kd>100.0</kd>
    <mu1>1.0</mu1>
    <mu2>1.0</mu2>
    <maxVel>1.0</maxVel>
    <maxContacts>1</maxContacts>
  </gazebo>
  <gazebo reference="rh_foot">
    <kp>1000000.0</kp>
    <kd>100.0</kd>
    <mu1>1.0</mu1>
    <mu2>1.0</mu2>
    <maxVel>1.0</maxVel>
    <maxContacts>1</maxContacts>
    <material>Gazebo/Black</material>
  </gazebo>
</robot>
